<?xml version="1.0" ?>
<sdf version="1.7">
  <model name='truck'>
    <link name='base'>
      <inertial>
        <pose>0 0 0 0 -0 0</pose>
        <mass>5.05371</mass>
        <inertia>
          <ixx>0.00627</ixx>
          <ixy>0.00089</ixy>
          <ixz>0.00036</ixz>
          <iyy>0.04284</iyy>
          <iyz>-0.00013</iyz>
          <izz>0.04836</izz>
        </inertia>
      </inertial>
      <visual name='base_visual'>
        <pose>0 0 0 1.5708 -0 1.5708</pose>
        <geometry>
          <mesh>
            <scale>1 1 1</scale>
            <uri>model://truck_description/meshes/group5.obj</uri>
          </mesh>
        </geometry>
      </visual>
    </link>
    <joint name='left_rear_axle' type='revolute'>
      <pose relative_to='base'>-0.2025 0.11168 -0.01329 0 -0 0</pose>
      <parent>base</parent>
      <child>rear_left_wheel</child>
      <axis>
        <xyz>0 1 0</xyz>
        <limit>
          <lower>-1e+16</lower>
          <upper>1e+16</upper>
        </limit>
        <dynamics>
          <damping>0</damping>
          <friction>0</friction>
          <spring_reference>0</spring_reference>
          <spring_stiffness>0</spring_stiffness>
        </dynamics>
      </axis>
    </joint>
    <link name='rear_left_wheel'>
      <pose relative_to='left_rear_axle'>0 0 0 0 -0 0</pose>
      <inertial>
        <pose>0 0 0 0 -0 0</pose>
        <mass>0.10194</mass>
        <inertia>
          <ixx>0.00012</ixx>
          <ixy>0</ixy>
          <ixz>0</ixz>
          <iyy>0.00018</iyy>
          <iyz>0</iyz>
          <izz>0.00012</izz>
        </inertia>
      </inertial>
      <collision name='rear_left_wheel_collision'>
        <pose>0 0.0195 0 1.5708 -0 0</pose>
        <geometry>
          <cylinder>
            <length>0.058</length>
            <radius>0.055</radius>
          </cylinder>
        </geometry>
        <surface>
          <friction>
            <torsional>
              <coefficient>1.0</coefficient>
            </torsional>
            <ode>
              <mu>1.0</mu>
              <mu2>1.0</mu2>
            </ode>
          </friction>
        </surface>
      </collision>
      <visual name='rear_left_wheel_visual'>
        <pose>0.2025 -0.11168 0.01329 1.5708 -0 1.5708</pose>
        <geometry>
          <mesh>
            <scale>1 1 1</scale>
            <uri>model://truck_description/meshes/group4.obj</uri>
          </mesh>
        </geometry>
      </visual>
    </link>
    <joint name='left_steering_joint' type='revolute'>
      <pose relative_to='base'>0.2025 0.10668 -0.01329 0 -0 0</pose>
      <parent>base</parent>
      <child>front_left_cup</child>
      <axis>
        <xyz>0 0 1</xyz>
        <limit>
          <lower>-1.0</lower>
          <upper>+1.0</upper>
        </limit>
        <dynamics>
          <damping>0</damping>
          <friction>0</friction>
          <spring_reference>0</spring_reference>
          <spring_stiffness>0</spring_stiffness>
        </dynamics>
      </axis>
    </joint>
    <link name='front_left_cup'>
      <pose relative_to='left_steering_joint'>0 0 0 0 -0 0</pose>
      <inertial>
        <pose>0 0 0 0 -0 0</pose>
        <mass>0.0001</mass>
        <inertia>
          <ixx>0</ixx>
          <ixy>0</ixy>
          <ixz>0</ixz>
          <iyy>0</iyy>
          <iyz>0</iyz>
          <izz>0</izz>
        </inertia>
      </inertial>
    </link>
    <joint name='front_left_wheel_axle' type='revolute'>
      <pose relative_to='front_left_cup'>0 0.0075 0 0 -0 0</pose>
      <parent>front_left_cup</parent>
      <child>front_left_wheel</child>
      <axis>
        <xyz>0 -1 0</xyz>
        <limit>
          <lower>-1e+16</lower>
          <upper>1e+16</upper>
        </limit>
        <dynamics>
          <damping>0</damping>
          <friction>0</friction>
          <spring_reference>0</spring_reference>
          <spring_stiffness>0</spring_stiffness>
        </dynamics>
      </axis>
    </joint>
    <link name='front_left_wheel'>
      <pose relative_to='front_left_wheel_axle'>0 0 0 0 -0 0</pose>
      <inertial>
        <pose>0 0 0 0 -0 0</pose>
        <mass>0.0001</mass>
        <inertia>
          <ixx>0.00012</ixx>
          <ixy>0</ixy>
          <ixz>0</ixz>
          <iyy>0.00018</iyy>
          <iyz>0</iyz>
          <izz>0.00012</izz>
        </inertia>
      </inertial>
      <collision name='front_left_wheel_collision'>
        <pose>0 0.017 0 1.5708 -0 0</pose>
        <geometry>
          <cylinder>
            <length>0.058</length>
            <radius>0.055</radius>
          </cylinder>
        </geometry>
        <surface>
          <friction>
            <torsional>
              <coefficient>1.0</coefficient>
            </torsional>
            <ode>
              <mu>1.0</mu>
              <mu2>1.0</mu2>
            </ode>
          </friction>
        </surface>
      </collision>
      <visual name='front_left_wheel_visual'>
        <pose>-0.2025 -0.11418 0.01329 1.5708 -0 1.5708</pose>
        <geometry>
          <mesh>
            <scale>1 1 1</scale>
            <uri>model://truck_description/meshes/group3.obj</uri>
          </mesh>
        </geometry>
      </visual>
    </link>
    <joint name='right_rear_axle' type='revolute'>
      <pose relative_to='base'>-0.2025 -0.11168 -0.01329 0 -0 0</pose>
      <parent>base</parent>
      <child>rear_right_wheel</child>
      <axis>
        <xyz>0 1 0</xyz>
        <limit>
          <lower>-1e+16</lower>
          <upper>1e+16</upper>
        </limit>
        <dynamics>
          <damping>0</damping>
          <friction>0</friction>
          <spring_reference>0</spring_reference>
          <spring_stiffness>0</spring_stiffness>
        </dynamics>
      </axis>
    </joint>
    <link name='rear_right_wheel'>
      <pose relative_to='right_rear_axle'>0 0 0 0 -0 0</pose>
      <inertial>
        <pose>0 0 0 0 -0 0</pose>
        <mass>0.10194</mass>
        <inertia>
          <ixx>0.00012</ixx>
          <ixy>0</ixy>
          <ixz>0</ixz>
          <iyy>0.00018</iyy>
          <iyz>0</iyz>
          <izz>0.00012</izz>
        </inertia>
      </inertial>
      <collision name='rear_right_wheel_collision'>
        <pose>0 -0.0195 0 1.5708 -0 0</pose>
        <geometry>
          <cylinder>
            <length>0.058</length>
            <radius>0.055</radius>
          </cylinder>
        </geometry>
        <surface>
          <friction>
            <torsional>
              <coefficient>1.0</coefficient>
            </torsional>
            <ode>
              <mu>1.0</mu>
              <mu2>1.0</mu2>
            </ode>
          </friction>
        </surface>
      </collision>
      <visual name='rear_right_wheel_visual'>
        <pose>0.2025 0.11168 0.01329 1.5708 -0 1.5708</pose>
        <geometry>
          <mesh>
            <scale>1 1 1</scale>
            <uri>model://truck_description/meshes/group1.obj</uri>
          </mesh>
        </geometry>
      </visual>
    </link>
    <joint name='right_steering_joint' type='revolute'>
      <pose relative_to='base'>0.2025 -0.10668 -0.01329 0 -0 0</pose>
      <parent>base</parent>
      <child>front_right_cup</child>
      <axis>
        <xyz>0 0 1</xyz>
        <limit>
          <lower>-1.0</lower>
          <upper>+1.0</upper>
        </limit>
        <dynamics>
          <damping>0</damping>
          <friction>0</friction>
          <spring_reference>0</spring_reference>
          <spring_stiffness>0</spring_stiffness>
        </dynamics>
      </axis>
    </joint>
    <link name='front_right_cup'>
      <pose relative_to='right_steering_joint'>0 0 0 0 -0 0</pose>
      <inertial>
        <pose>0 0 0 0 -0 0</pose>
        <mass>0.0001</mass>
        <inertia>
          <ixx>0</ixx>
          <ixy>0</ixy>
          <ixz>0</ixz>
          <iyy>0</iyy>
          <iyz>0</iyz>
          <izz>0</izz>
        </inertia>
      </inertial>
    </link>
    <joint name='front_right_wheel_axle' type='revolute'>
      <pose relative_to='front_right_cup'>0 -0.0075 0 0 -0 0</pose>
      <parent>front_right_cup</parent>
      <child>front_right_wheel</child>
      <axis>
        <xyz>0 -1 0</xyz>
        <limit>
          <lower>-1e+16</lower>
          <upper>1e+16</upper>
        </limit>
        <dynamics>
          <damping>0</damping>
          <friction>0</friction>
          <spring_reference>0</spring_reference>
          <spring_stiffness>0</spring_stiffness>
        </dynamics>
      </axis>
    </joint>
    <link name='front_right_wheel'>
      <pose relative_to='front_right_wheel_axle'>0 0 0 0 -0 0</pose>
      <inertial>
        <pose>0 0 0 0 -0 0</pose>
        <mass>0.0001</mass>
        <inertia>
          <ixx>0.00012</ixx>
          <ixy>0</ixy>
          <ixz>0</ixz>
          <iyy>0.00018</iyy>
          <iyz>0</iyz>
          <izz>0.00012</izz>
        </inertia>
      </inertial>
      <collision name='front_right_wheel_collision'>
        <pose>0 -0.017 0 1.5708 -0 0</pose>
        <geometry>
          <cylinder>
            <length>0.058</length>
            <radius>0.055</radius>
          </cylinder><coefficient>1.0</coefficient>
        </geometry>
        <surface>
          <friction>
            <torsional>
              <coefficient>1.0</coefficient>
            </torsional>
            <ode>
              <mu>1.0</mu>
              <mu2>1.0</mu2>
            </ode>
          </friction>
        </surface>
      </collision>
      <visual name='front_right_wheel_visual'>
        <pose>-0.2025 0.11418 0.01329 1.5708 -0 1.5708</pose>
        <geometry>
          <mesh>
            <scale>1 1 1</scale>
            <uri>model://truck_description/meshes/group6.obj</uri>
          </mesh>
        </geometry>
      </visual>
    </link>
    <static>0</static>
    <plugin name='AckermannControlPlugin' filename='libtruck_gazebo_ackermann_model.so'>
      <config_path>/home/dasimagin/truck/packages/model/config/model.yaml</config_path>
      <steering>
        <error>0.1</error>
        <torque>0.3</torque>
        <left_joint>left_steering_joint</left_joint>
        <right_joint>right_steering_joint</right_joint>
      </steering>
      <rear>
        <pd>0.1 0.0</pd>
        <torque>1000.0</torque>
        <left_joint>left_rear_axle</left_joint>
        <right_joint>right_rear_axle</right_joint>
      </rear>
    </plugin>
  </model>
</sdf>
