<?xml version="1.0" ?>
<sdf version="1.7">
  <model name="truck">
    <link name="base">
      <inertial>
        <pose>0 0 0 0 0 0</pose>
        <mass>2.05371</mass>
        <inertia>
          <ixx>0.00627</ixx>
          <ixy>0.0</ixy>
          <ixz>0.0</ixz>
          <iyy>0.04284</iyy>
          <iyz>0.0</iyz>
          <izz>0.04836</izz>
        </inertia>
      </inertial>
      <visual name="base_visual">
        <pose>0 0 0 1.5708 0 1.5708</pose>
        <geometry>
          <mesh>
            <scale>1 1 1</scale>
            <uri>model://truck/meshes/group5.obj</uri>
          </mesh>
        </geometry>
      </visual>
    </link>

    <include>
      <uri>model://rplidar_s2</uri>
      <pose relative_to="base_to_lidar">0 0 0 0 0 0</pose>
    </include>

    <joint name="base_to_lidar" type="fixed">
      <pose relative_to="base">0 0 0.30 0 0 0</pose>
      <parent>base</parent>
      <child>rplidar_s2::lidar_link</child>
    </joint>

    <joint name="base_to_camera" type="fixed">
      <pose relative_to="base">0.2 0 0.04 0 0 0</pose>
      <parent>base</parent>
      <child>d455::camera_link</child>
    </joint>

    <include>
      <uri>model://d455</uri>
      <pose relative_to="base_to_camera">0 0.0475 0 0 0 0</pose>
    </include>

    <joint name="left_rear_axle" type="revolute">
      <pose relative_to="base">-0.2025 0.11168 -0.01329 0 0 0</pose>
      <parent>base</parent>
      <child>rear_left_wheel</child>
      <axis>
        <xyz>0 1 0</xyz>
      </axis>
    </joint>

    <link name="rear_left_wheel">
      <pose relative_to="left_rear_axle">0 0 0 0 0 0</pose>
      <inertial>
        <pose>0 0 0 0 0 0</pose>
        <mass>0.10194</mass>
        <inertia>
          <ixx>0.00012</ixx>
          <ixy>0</ixy>
          <ixz>0</ixz>
          <iyy>0.00018</iyy>
          <iyz>0</iyz>
          <izz>0.00012</izz>
        </inertia>
      </inertial>
      <collision name="rear_left_wheel_collision">
        <pose>0 0.0195 0 1.5708 0 0</pose>
        <geometry>
          <cylinder>
            <length>0.058</length>
            <radius>0.055</radius>
          </cylinder>
        </geometry>
      </collision>
      <visual name="rear_left_wheel_visual">
        <pose>0.2025 -0.11168 0.01329 1.5708 0 1.5708</pose>
        <geometry>
          <mesh>
            <scale>1 1 1</scale>
            <uri>model://truck/meshes/group4.obj</uri>
          </mesh>
        </geometry>
      </visual>
    </link>

    <joint name="left_steering_joint" type="revolute">
      <pose relative_to="base">0.2025 0.10668 -0.01329 0 0 0</pose>
      <parent>base</parent>
      <child>front_left_cup</child>
      <axis>
        <xyz>0 0 1</xyz>
        <limit>
          <lower>-1.0</lower>
          <upper>+1.0</upper>
        </limit>
      </axis>
    </joint>

    <link name="front_left_cup">
      <pose relative_to="left_steering_joint">0 0 0 0 0 0</pose>
      <inertial>
        <pose>0 0 0 0 0 0</pose>
        <mass>0.0001</mass>
        <inertia>
          <ixx>0.00001</ixx>
          <ixy>0</ixy>
          <ixz>0</ixz>
          <iyy>0.00001</iyy>
          <iyz>0</iyz>
          <izz>0.00001</izz>
        </inertia>
      </inertial>
    </link>

    <joint name="front_left_wheel_axle" type="revolute">
      <pose relative_to="front_left_cup">0 0.0075 0 0 0 0</pose>
      <parent>front_left_cup</parent>
      <child>front_left_wheel</child>
      <axis>
        <xyz>0 -1 0</xyz>
      </axis>
    </joint>

    <link name="front_left_wheel">
      <pose relative_to="front_left_wheel_axle">0 0 0 0 0 0</pose>
      <inertial>
        <pose>0 0 0 0 0 0</pose>
        <mass>0.10194</mass>
        <inertia>
          <ixx>0.00012</ixx>
          <ixy>0</ixy>
          <ixz>0</ixz>
          <iyy>0.00018</iyy>
          <iyz>0</iyz>
          <izz>0.00012</izz>
        </inertia>
      </inertial>
      <collision name="front_left_wheel_collision">
        <pose>0 0.017 0 1.5708 0 0</pose>
        <geometry>
          <cylinder>
            <length>0.058</length>
            <radius>0.055</radius>
          </cylinder>
        </geometry>
      </collision>
      <visual name="front_left_wheel_visual">
        <pose>-0.2025 -0.11418 0.01329 1.5708 0 1.5708</pose>
        <geometry>
          <mesh>
            <scale>1 1 1</scale>
            <uri>model://truck/meshes/group3.obj</uri>
          </mesh>
        </geometry>
      </visual>
    </link>

    <joint name="right_rear_axle" type="revolute">
      <pose relative_to="base">-0.2025 -0.11168 -0.01329 0 0 0</pose>
      <parent>base</parent>
      <child>rear_right_wheel</child>
      <axis>
        <xyz>0 1 0</xyz>
      </axis>
    </joint>

    <link name="rear_right_wheel">
      <pose relative_to="right_rear_axle">0 0 0 0 0 0</pose>
      <inertial>
        <pose>0 0 0 0 0 0</pose>
        <mass>0.10194</mass>
        <inertia>
          <ixx>0.00012</ixx>
          <ixy>0</ixy>
          <ixz>0</ixz>
          <iyy>0.00018</iyy>
          <iyz>0</iyz>
          <izz>0.00012</izz>
        </inertia>
      </inertial>
      <collision name="rear_right_wheel_collision">
        <pose>0 -0.0195 0 1.5708 0 0</pose>
        <geometry>
          <cylinder>
            <length>0.058</length>
            <radius>0.055</radius>
          </cylinder>
        </geometry>
      </collision>
      <visual name="rear_right_wheel_visual">
        <pose>0.2025 0.11168 0.01329 1.5708 0 1.5708</pose>
        <geometry>
          <mesh>
            <scale>1 1 1</scale>
            <uri>model://truck/meshes/group1.obj</uri>
          </mesh>
        </geometry>
      </visual>
    </link>

    <joint name="right_steering_joint" type="revolute">
      <pose relative_to="base">0.2025 -0.10668 -0.01329 0 0 0</pose>
      <parent>base</parent>
      <child>front_right_cup</child>
      <axis>
        <xyz>0 0 1</xyz>
      </axis>
    </joint>

    <link name="front_right_cup">
      <pose relative_to="right_steering_joint">0 0 0 0 0 0</pose>
      <inertial>
        <pose>0 0 0 0 0 0</pose>
        <mass>0.0001</mass>
        <inertia>
          <ixx>0.00001</ixx>
          <ixy>0</ixy>
          <ixz>0</ixz>
          <iyy>0.00001</iyy>
          <iyz>0</iyz>
          <izz>0.00001</izz>
        </inertia>
      </inertial>
    </link>

    <joint name="front_right_wheel_axle" type="revolute">
      <pose relative_to="front_right_cup">0 -0.0075 0 0 0 0</pose>
      <parent>front_right_cup</parent>
      <child>front_right_wheel</child>
      <axis>
        <xyz>0 -1 0</xyz>
      </axis>
    </joint>

    <link name="front_right_wheel">
      <pose relative_to="front_right_wheel_axle">0 0 0 0 0 0</pose>
      <inertial>
        <pose>0 0 0 0 0 0</pose>
        <mass>0.10194</mass>
        <inertia>
          <ixx>0.00012</ixx>
          <ixy>0</ixy>
          <ixz>0</ixz>
          <iyy>0.00018</iyy>
          <iyz>0</iyz>
          <izz>0.00012</izz>
        </inertia>
      </inertial>
      <collision name="front_right_wheel_collision">
        <pose>0 -0.017 0 1.5708 0 0</pose>
        <geometry>
          <cylinder>
            <length>0.058</length>
            <radius>0.055</radius>
          </cylinder>
        </geometry>
      </collision>
      <visual name="front_right_wheel_visual">
        <pose>-0.2025 0.11418 0.01329 1.5708 0 1.5708</pose>
        <geometry>
          <mesh>
            <scale>1 1 1</scale>
            <uri>model://truck/meshes/group6.obj</uri>
          </mesh>
        </geometry>
      </visual>
    </link>

    <plugin name="AckermannControlPlugin" filename="libtruck_gazebo_ackermann_model.so">
      <config_path>/truck/packages/model/config/model.yaml</config_path>
      <steering>
        <error>0.03</error>
        <velocity>120</velocity>
        <torque>0.5</torque>
        <left_joint>left_steering_joint</left_joint>
        <right_joint>right_steering_joint</right_joint>
      </steering>
      <rear>
        <pd>0.1 0.0</pd>
        <torque>10.0</torque>
        <left_joint>left_rear_axle</left_joint>
        <right_joint>right_rear_axle</right_joint>
      </rear>
    </plugin>

    <plugin name="MotorOdometryPlugin" filename="libtruck_gazebo_motor_odometry.so">
      <config_path>/truck/packages/model/config/model.yaml</config_path>
      <left_joint>left_rear_axle</left_joint>
      <right_joint>right_rear_axle</right_joint>
      <period>0.02</period>
    </plugin>
  </model>
</sdf>
